Workbook

Sheet Formula_Demo
A1: Formula Demo – each function on live Sample Superstore data (change yellow inputs)
A2: Data tab = first 500 rows of the real Sample Superstore dataset. Column C shows the formula used.
A3: Input: Region | B3: West
A4: Input: Category | B4: Technology
A5: Input: Segment | B5: Consumer
A6: Input: State | B6: California
A7: Input: Sub-Category | B7: Phones
A9: 1. SUMIF vs SUMIFS
A10: SUMIF – sales for region | B10: =SUMIF(OrderRegion,B3,SalesAmt) -> 37781.637 | C10: SUMIF(OrderRegion,B3,SalesAmt)
A11: SUMIFS – region + category | B11: =SUMIFS(SalesAmt,OrderRegion,B3,Category,B4) -> 15937.808 | C11: SUMIFS(SalesAmt,OrderRegion,B3,Category,B4)
A12: SUMIFS – region + category + segment | B12: =SUMIFS(SalesAmt,OrderRegion,B3,Category,B4,Segment,B5) -> 14840.562 | C12: SUMIFS(SalesAmt,OrderRegion,B3,Category,B4,Segment,B5)
A13: SUMIFS – with operator: discount > 30% | B13: =SUMIFS(SalesAmt,OrderRegion,B3,Discount,">0.3") -> 1651.577 | C13: SUMIFS(SalesAmt,OrderRegion,B3,Discount,">0.3")
A14: SUMIFS – total loss (profit < 0) in region | B14: =SUMIFS(ProfitAmt,OrderRegion,B3,ProfitAmt,"<0") -> -1429.8178 | C14: SUMIFS(ProfitAmt,OrderRegion,B3,ProfitAmt,"<0")
A16: 2. COUNTIF / COUNTIFS / AVERAGEIFS
A17: COUNTIF – rows in region | B17: =COUNTIF(OrderRegion,B3) -> 154 | C17: COUNTIF(OrderRegion,B3)
A18: COUNTIFS – region + category | B18: =COUNTIFS(OrderRegion,B3,Category,B4) -> 32 | C18: COUNTIFS(OrderRegion,B3,Category,B4)
A19: COUNTIF wildcard – cities starting with "San" | B19: =COUNTIF(City,"San*") -> 50 | C19: COUNTIF(City,"San*")
A20: COUNTIF – discount of 40% or more | B20: =COUNTIF(Discount,">=0.4") -> 67 | C20: COUNTIF(Discount,">=0.4")
A21: AVERAGEIFS – avg sales (region + category) | B21: =IFERROR(AVERAGEIFS(SalesAmt,OrderRegion,B3,Category,B4),0) -> 498.0565 | C21: IFERROR(AVERAGEIFS(SalesAmt,OrderRegion,B3,Category,B4),0)
A22: COUNTBLANK – blank cells in Sales column | B22: =COUNTBLANK(SalesAmt) -> 0 | C22: COUNTBLANK(SalesAmt)
A24: 3. Lookups: VLOOKUP / XLOOKUP / INDEX-MATCH
A25: VLOOKUP – region of state B6 | B25: =VLOOKUP(B6,Lookups!$A$2:$B$50,2,FALSE()) -> West | C25: VLOOKUP(B6,Lookups!$A$2:$B$50,2,FALSE)
A26: XLOOKUP – region of state B6 | B26: =_xlfn.xlookup(B6,StateList,StateRegion,"Not found") -> #NAME? | C26: XLOOKUP(B6,StateList,StateRegion,"Not found")
A27: INDEX/MATCH – category of sub-category B7 | B27: =INDEX(SubCatCat,MATCH(B7,SubCatName,0)) -> Technology | C27: INDEX(SubCatCat,MATCH(B7,SubCatName,0))
A28: INDEX/MATCH – LEFT lookup (first sub-category in B4) | B28: =INDEX(SubCatName,MATCH(B4,SubCatCat,0)) -> Accessories | C28: INDEX(SubCatName,MATCH(B4,SubCatCat,0))
A29: XLOOKUP – not found (custom message) | B29: =_xlfn.xlookup("Atlantis",StateList,StateRegion,"Not found") -> #NAME? | C29: XLOOKUP("Atlantis",StateList,StateRegion,"Not found")
A30: VLOOKUP – not found wrapped in IFERROR | B30: =IFERROR(VLOOKUP("Atlantis",Lookups!$A$2:$B$50,2,FALSE()),"Not found") -> Not found | C30: IFERROR(VLOOKUP("Atlantis",Lookups!$A$2:$B$50,2,FALSE),"Not found")
A32: 4. IF logic
A33: IF – is region profitable? | B33: =IF(SUMIFS(ProfitAmt,OrderRegion,B3)>0,"Profitable","Loss-making") -> Profitable | C33: IF(SUMIFS(ProfitAmt,OrderRegion,B3)>0,"Profitable","Loss-making")
A34: Nested IF – size of SUMIFS total | B34: =IF(B11>=50000,"High",IF(B11>=20000,"Medium","Low")) -> Low | C34: IF(B11>=50000,"High",IF(B11>=20000,"Medium","Low"))
A35: IF + AND – segment health check | B35: =IF(AND(B17>50,B21>200),"Strong","Review") -> Strong | C35: IF(AND(B17>50,B21>200),"Strong","Review")
A37: 5. Text functions
A38: Raw city input | B38: los ANGELES
A39: Raw location string input | B39: Henderson|Kentucky|42420
A40: TRIM – remove extra spaces | B40: =TRIM(B38) -> los ANGELES | C40: TRIM(B38)
A41: PROPER(TRIM) – clean city | B41: =PROPER(TRIM(B38)) -> Los Angeles | C41: PROPER(TRIM(B38))
A42: UPPER | B42: =UPPER(TRIM(B38)) -> LOS ANGELES | C42: UPPER(TRIM(B38))
A43: LEN – raw vs clean length | B43: =LEN(B38)&" vs "&LEN(TRIM(B38)) -> 14 vs 11 | C43: LEN(B38)&" vs "&LEN(TRIM(B38))
A44: LEFT – first 3 letters of state | B44: =UPPER(LEFT(B6,3)) -> CAL | C44: UPPER(LEFT(B6,3))
A45: FIND – position of first | | B45: =FIND("|",B39) -> 10 | C45: FIND("|",B39)
...

Sheet Data
A1: Row ID | B1: Ship Mode | C1: Segment | D1: Country | E1: City | F1: State | G1: Postal Code | H1: Region | I1: Category | J1: Sub-Category | K1: Sales | L1: Quantity | M1: Discount | N1: Profit | O1: Location Code UPPER/LEFT/& | P1: City Clean PROPER(TRIM) | Q1: Region via State VLOOKUP | R1: Region Check IF | S1: Category via Sub-Cat INDEX/MATCH | T1: Margin % IF + division | U1: Profit Status Nested IF | V1: Discount Band Nested IF | W1: Ship Priority IF/OR | X1: Unit Price ROUND
A2: 1 | B2: Second Class | C2: Consumer | D2: United States | E2: Henderson | F2: Kentucky | G2: 42420 | H2: South | I2: Furniture | J2: Bookcases | K2: 261.96 | L2: 2 | M2: 0 | N2: 41.9136 | O2: =UPPER(LEFT(F2,3))&"-"&G2 -> KEN-42420 | P2: =PROPER(TRIM(E2)) -> Henderson | Q2: =IFERROR(VLOOKUP(F2,Lookups!$A$2:$B$50,2,FALSE()),"Not found") -> South | R2: =IF(Q2=H2,"Match","Mismatch") -> Match | S2: =IFERROR(INDEX(SubCatCat,MATCH(J2,SubCatName,0)),"Not found") -> Furniture | T2: =IF(K2=0,0,N2/K2) -> 0.16 | U2: =IF(N2<0,"Loss",IF(T2>=0.2,"High margin","Normal")) -> Normal | V2: =IF(M2=0,"No discount",IF(M2<=0.2,"Low",IF(M2<=0.4,"Medium","High"))) -> No discount | W2: =IF(OR(B2="Same Day",B2="First Class"),"Fast","Standard") -> Standard | X2: =ROUND(K2/L2,2) -> 130.98
A3: 2 | B3: Second Class | C3: Consumer | D3: United States | E3: Henderson | F3: Kentucky | G3: 42420 | H3: South | I3: Furniture | J3: Chairs | K3: 731.94 | L3: 3 | M3: 0 | N3: 219.582 | O3: =UPPER(LEFT(F3,3))&"-"&G3 -> KEN-42420 | P3: =PROPER(TRIM(E3)) -> Henderson | Q3: =IFERROR(VLOOKUP(F3,Lookups!$A$2:$B$50,2,FALSE()),"Not found") -> South | R3: =IF(Q3=H3,"Match","Mismatch") -> Match | S3: =IFERROR(INDEX(SubCatCat,MATCH(J3,SubCatName,0)),"Not found") -> Furniture | T3: =IF(K3=0,0,N3/K3) -> 0.3 | U3: =IF(N3<0,"Loss",IF(T3>=0.2,"High margin","Normal")) -> High margin | V3: =IF(M3=0,"No discount",IF(M3<=0.2,"Low",IF(M3<=0.4,"Medium","High"))) -> No discount | W3: =IF(OR(B3="Same Day",B3="First Class"),"Fast","Standard") -> Standard | X3: =ROUND(K3/L3,2) -> 243.98
A4: 3 | B4: Second Class | C4: Corporate | D4: United States | E4: Los Angeles | F4: California | G4: 90036 | H4: West | I4: Office Supplies | J4: Labels | K4: 14.62 | L4: 2 | M4: 0 | N4: 6.8714 | O4: =UPPER(LEFT(F4,3))&"-"&G4 -> CAL-90036 | P4: =PROPER(TRIM(E4)) -> Los Angeles | Q4: =IFERROR(VLOOKUP(F4,Lookups!$A$2:$B$50,2,FALSE()),"Not found") -> West | R4: =IF(Q4=H4,"Match","Mismatch") -> Match | S4: =IFERROR(INDEX(SubCatCat,MATCH(J4,SubCatName,0)),"Not found") -> Office Supplies | T4: =IF(K4=0,0,N4/K4) -> 0.47 | U4: =IF(N4<0,"Loss",IF(T4>=0.2,"High margin","Normal")) -> High margin | V4: =IF(M4=0,"No discount",IF(M4<=0.2,"Low",IF(M4<=0.4,"Medium","High"))) -> No discount | W4: =IF(OR(B4="Same Day",B4="First Class"),"Fast","Standard") -> Standard | X4: =ROUND(K4/L4,2) -> 7.31
A5: 4 | B5: Standard Class | C5: Consumer | D5: United States | E5: Fort Lauderdale | F5: Florida | G5: 33311 | H5: South | I5: Furniture | J5: Tables | K5: 957.5775 | L5: 5 | M5: 0.45 | N5: -383.031 | O5: =UPPER(LEFT(F5,3))&"-"&G5 -> FLO-33311 | P5: =PROPER(TRIM(E5)) -> Fort Lauderdale | Q5: =IFERROR(VLOOKUP(F5,Lookups!$A$2:$B$50,2,FALSE()),"Not found") -> South | R5: =IF(Q5=H5,"Match","Mismatch") -> Match | S5: =IFERROR(INDEX(SubCatCat,MATCH(J5,SubCatName,0)),"Not found") -> Furniture | T5: =IF(K5=0,0,N5/K5) -> -0.4 | U5: =IF(N5<0,"Loss",IF(T5>=0.2,"High margin","Normal")) -> Loss | V5: =IF(M5=0,"No discount",IF(M5<=0.2,"Low",IF(M5<=0.4,"Medium","High"))) -> High | W5: =IF(OR(B5="Same Day",B5="First Class"),"Fast","Standard") -> Standard | X5: =ROUND(K5/L5,2) -> 191.52
A6: 5 | B6: Standard Class | C6: Consumer | D6: United States | E6: Fort Lauderdale | F6: Florida | G6: 33311 | H6: South | I6: Office Supplies | J6: Storage | K6: 22.368 | L6: 2 | M6: 0.2 | N6: 2.5164 | O6: =UPPER(LEFT(F6,3))&"-"&G6 -> FLO-33311 | P6: =PROPER(TRIM(E6)) -> Fort Lauderdale | Q6: =IFERROR(VLOOKUP(F6,Lookups!$A$2:$B$50,2,FALSE()),"Not found") -> South | R6: =IF(Q6=H6,"Match","Mismatch") -> Match | S6: =IFERROR(INDEX(SubCatCat,MATCH(J6,SubCatName,0)),"Not found") -> Office Supplies | T6: =IF(K6=0,0,N6/K6) -> 0.1125 | U6: =IF(N6<0,"Loss",IF(T6>=0.2,"High margin","Normal")) -> Normal | V6: =IF(M6=0,"No discount",IF(M6<=0.2,"Low",IF(M6<=0.4,"Medium","High"))) -> Low | W6: =IF(OR(B6="Same Day",B6="First Class"),"Fast","Standard") -> Standard | X6: =ROUND(K6/L6,2) -> 11.18
A7: 6 | B7: Standard Class | C7: Consumer | D7: United States | E7: Los Angeles | F7: California | G7: 90032 | H7: West | I7: Furniture | J7: Furnishings | K7: 48.86 | L7: 7 | M7: 0 | N7: 14.1694 | O7: =UPPER(LEFT(F7,3))&"-"&G7 -> CAL-90032 | P7: =PROPER(TRIM(E7)) -> Los Angeles | Q7: =IFERROR(VLOOKUP(F7,Lookups!$A$2:$B$50,2,FALSE()),"Not found") -> West | R7: =IF(Q7=H7,"Match","Mismatch") -> Match | S7: =IFERROR(INDEX(SubCatCat,MATCH(J7,SubCatName,0)),"Not found") -> Furniture | T7: =IF(K7=0,0,N7/K7) -> 0.29 | U7: =IF(N7<0,"Loss",IF(T7>=0.2,"High margin","Normal")) -> High margin | V7: =IF(M7=0,"No discount",IF(M7<=0.2,"Low",IF(M7<=0.4,"Medium","High"))) -> No discount | W7: =IF(OR(B7="Same Day",B7="First Class"),"Fast","Standard") -> Standard | X7: =ROUND(K7/L7,2) -> 6.98
A8: 7 | B8: Standard Class | C8: Consumer | D8: United States | E8: Los Angeles | F8: California | G8: 90032 | H8: West | I8: Office Supplies | J8: Art | K8: 7.28 | L8: 4 | M8: 0 | N8: 1.9656 | O8: =UPPER(LEFT(F8,3))&"-"&G8 -> CAL-90032 | P8: =PROPER(TRIM(E8)) -> Los Angeles | Q8: =IFERROR(VLOOKUP(F8,Lookups!$A$2:$B$50,2,FALSE()),"Not found") -> West | R8: =IF(Q8=H8,"Match","Mismatch") -> Match | S8: =IFERROR(INDEX(SubCatCat,MATCH(J8,SubCatName,0)),"Not found") -> Office Supplies | T8: =IF(K8=0,0,N8/K8) -> 0.27 | U8: =IF(N8<0,"Loss",IF(T8>=0.2,"High margin","Normal")) -> High margin | V8: =IF(M8=0,"No discount",IF(M8<=0.2,"Low",IF(M8<=0.4,"Medium","High"))) -> No discount | W8: =IF(OR(B8="Same Day",B8="First Class"),"Fast","Standard") -> Standard | X8: =ROUND(K8/L8,2) -> 1.82
A9: 8 | B9: Standard Class | C9: Consumer | D9: United States | E9: Los Angeles | F9: California | G9: 90032 | H9: West | I9: Technology | J9: Phones | K9: 907.152 | L9: 6 | M9: 0.2 | N9: 90.7152 | O9: =UPPER(LEFT(F9,3))&"-"&G9 -> CAL-90032 | P9: =PROPER(TRIM(E9)) -> Los Angeles | Q9: =IFERROR(VLOOKUP(F9,Lookups!$A$2:$B$50,2,FALSE()),"Not found") -> West | R9: =IF(Q9=H9,"Match","Mismatch") -> Match | S9: =IFERROR(INDEX(SubCatCat,MATCH(J9,SubCatName,0)),"Not found") -> Technology | T9: =IF(K9=0,0,N9/K9) -> 0.1 | U9: =IF(N9<0,"Loss",IF(T9>=0.2,"High margin","Normal")) -> Normal | V9: =IF(M9=0,"No discount",IF(M9<=0.2,"Low",IF(M9<=0.4,"Medium","High"))) -> Low | W9: =IF(OR(B9="Same Day",B9="First Class"),"Fast","Standard") -> Standard | X9: =ROUND(K9/L9,2) -> 151.19
A10: 9 | B10: Standard Class | C10: Consumer | D10: United States | E10: Los Angeles | F10: California | G10: 90032 | H10: West | I10: Office Supplies | J10: Binders | K10: 18.504 | L10: 3 | M10: 0.2 | N10: 5.7825 | O10: =UPPER(LEFT(F10,3))&"-"&G10 -> CAL-90032 | P10: =PROPER(TRIM(E10)) -> Los Angeles | Q10: =IFERROR(VLOOKUP(F10,Lookups!$A$2:$B$50,2,FALSE()),"Not found") -> West | R10: =IF(Q10=H10,"Match","Mismatch") -> Match | S10: =IFERROR(INDEX(SubCatCat,MATCH(J10,SubCatName,0)),"Not found") -> Office Supplies | T10: =IF(K10=0,0,N10/K10) -> 0.3125 | U10: =IF(N10<0,"Loss",IF(T10>=0.2,"High margin","Normal")) -> High margin | V10: =IF(M10=0,"No discount",IF(M10<=0.2,"Low",IF(M10<=0.4,"Medium","High"))) -> Low | W10: =IF(OR(B10="Same Day",B10="First Class"),"Fast","Standard") -> Standard | X10: =ROUND(K10/L10,2) -> 6.17
A11: 10 | B11: Standard Class | C11: Consumer | D11: United States | E11: Los Angeles | F11: California | G11: 90032 | H11: West | I11: Office Supplies | J11: Appliances | K11: 114.9 | L11: 5 | M11: 0 | N11: 34.47 | O11: =UPPER(LEFT(F11,3))&"-"&G11 -> CAL-90032 | P11: =PROPER(TRIM(E11)) -> Los Angeles | Q11: =IFERROR(VLOOKUP(F11,Lookups!$A$2:$B$50,2,FALSE()),"Not found") -> West | R11: =IF(Q11=H11,"Match","Mismatch") -> Match | S11: =IFERROR(INDEX(SubCatCat,MATCH(J11,SubCatName,0)),"Not found") -> Office Supplies | T11: =IF(K11=0,0,N11/K11) -> 0.3 | U11: =IF(N11<0,"Loss",IF(T11>=0.2,"High margin","Normal")) -> High margin | V11: =IF(M11=0,"No discount",IF(M11<=0.2,"Low",IF(M11<=0.4,"Medium","High"))) -> No discount | W11: =IF(OR(B11="Same Day",B11="First Class"),"Fast","Standard") -> Standard | X11: =ROUND(K11/L11,2) -> 22.98
A12: 11 | B12: Standard Class | C12: Consumer | D12: United States | E12: Los Angeles | F12: California | G12: 90032 | H12: West | I12: Furniture | J12: Tables | K12: 1706.184 | L12: 9 | M12: 0.2 | N12: 85.3092 | O12: =UPPER(LEFT(F12,3))&"-"&G12 -> CAL-90032 | P12: =PROPER(TRIM(E12)) -> Los Angeles | Q12: =IFERROR(VLOOKUP(F12,Lookups!$A$2:$B$50,2,FALSE()),"Not found") -> West | R12: =IF(Q12=H12,"Match","Mismatch") -> Match | S12: =IFERROR(INDEX(SubCatCat,MATCH(J12,SubCatName,0)),"Not found") -> Furniture | T12: =IF(K12=0,0,N12/K12) -> 0.05 | U12: =IF(N12<0,"Loss",IF(T12>=0.2,"High margin","Normal")) -> Normal | V12: =IF(M12=0,"No discount",IF(M12<=0.2,"Low",IF(M12<=0.4,"Medium","High"))) -> Low | W12: =IF(OR(B12="Same Day",B12="First Class"),"Fast","Standard") -> Standard | X12: =ROUND(K12/L12,2) -> 189.58
A13: 12 | B13: Standard Class | C13: Consumer | D13: United States | E13: Los Angeles | F13: California | G13: 90032 | H13: West | I13: Technology | J13: Phones | K13: 911.424 | L13: 4 | M13: 0.2 | N13: 68.3568 | O13: =UPPER(LEFT(F13,3))&"-"&G13 -> CAL-90032 | P13: =PROPER(TRIM(E13)) -> Los Angeles | Q13: =IFERROR(VLOOKUP(F13,Lookups!$A$2:$B$50,2,FALSE()),"Not found") -> West | R13: =IF(Q13=H13,"Match","Mismatch") -> Match | S13: =IFERROR(INDEX(SubCatCat,MATCH(J13,SubCatName,0)),"Not found") -> Technology | T13: =IF(K13=0,0,N13/K13) -> 0.075 | U13: =IF(N13<0,"Loss",IF(T13>=0.2,"High margin","Normal")) -> Normal | V13: =IF(M13=0,"No discount",IF(M13<=0.2,"Low",IF(M13<=0.4,"Medium","High"))) -> Low | W13: =IF(OR(B13="Same Day",B13="First Class"),"Fast","Standard") -> Standard | X13: =ROUND(K13/L13,2) -> 227.86
... A501: 500 | B501: Standard Class | C501: Consumer | D501: United States | E501: Costa Mesa | F501: California | G501: 92627 | H501: West | I501: Furniture | J501: Furnishings | K501: 69.3 | L501: 9 | M501: 0 | N501: 22.869 | O501: =UPPER(LEFT(F501,3))&"-"&G501 -> CAL-92627 | P501: =PROPER(TRIM(E501)) -> Costa Mesa | Q501: =IFERROR(VLOOKUP(F501,Lookups!$A$2:$B$50,2,FALSE()),"Not found") -> West | R501: =IF(Q501=H501,"Match","Mismatch") -> Match | S501: =IFERROR(INDEX(SubCatCat,MATCH(J501,SubCatName,0)),"Not found") -> Furniture | T501: =IF(K501=0,0,N501/K501) -> 0.33 | U501: =IF(N501<0,"Loss",IF(T501>=0.2,"High margin","Normal")) -> High margin | V501: =IF(M501=0,"No discount",IF(M501<=0.2,"Low",IF(M501<=0.4,"Medium","High"))) -> No discount | W501: =IF(OR(B501="Same Day",B501="First Class"),"Fast","Standard") -> Standard | X501: =ROUND(K501/L501,2) -> 7.7

Sheet Lookups
A1: State | B1: Region | D1: Sub-Category | E1: Category | G1: Lookup tables derived from the full Sample Superstore dataset (49 states, 17 sub-categories).
A2: Alabama | B2: South | D2: Accessories | E2: Technology
A3: Arizona | B3: West | D3: Appliances | E3: Office Supplies
A4: Arkansas | B4: South | D4: Art | E4: Office Supplies
A5: California | B5: West | D5: Binders | E5: Office Supplies
A6: Colorado | B6: West | D6: Bookcases | E6: Furniture
A7: Connecticut | B7: East | D7: Chairs | E7: Furniture
A8: Delaware | B8: East | D8: Copiers | E8: Technology
A9: District of Columbia | B9: East | D9: Envelopes | E9: Office Supplies
A10: Florida | B10: South | D10: Fasteners | E10: Office Supplies
A11: Georgia | B11: South | D11: Furnishings | E11: Furniture
A12: Idaho | B12: West | D12: Labels | E12: Office Supplies
A13: Illinois | B13: Central | D13: Machines | E13: Technology
... A18: Louisiana | B18: South | D18: Tables | E18: Furniture
A19: Maine | B19: East
A20: Maryland | B20: East
A21: Massachusetts | B21: East
A22: Michigan | B22: Central
A23: Minnesota | B23: Central
A24: Mississippi | B24: South
A25: Missouri | B25: Central
A26: Montana | B26: West
A27: Nebraska | B27: Central
A28: Nevada | B28: West
A29: New Hampshire | B29: East
A30: New Jersey | B30: East
... A50: Wyoming | B50: West

Sheet Notes
A1: When to use each formula
A3: Function | B3: Use it when… | C3: Watch out for
A4: SUMIF | B4: Total with ONE condition (e.g. sales for one region). | C4: Order: SUMIF(range, criteria, sum_range).
A5: SUMIFS | B5: Total with TWO or MORE conditions (region + category + discount). | C5: Sum_range comes FIRST in SUMIFS, last in SUMIF.
A6: COUNTIF / COUNTIFS | B6: Count rows matching one / many conditions; wildcards like "San*"; operators like ">=0.4". | C6: Numbers stored as text may not match.
A7: AVERAGEIFS | B7: Average of values meeting conditions (avg sale per region). | C7: Gives a divide-by-zero error if nothing matches – wrap in IFERROR.
A8: VLOOKUP | B8: Quick lookup when the key is the LEFT-most column of the table. | C8: Use FALSE for exact match; breaks if columns are inserted; cannot look left.
A9: XLOOKUP | B9: Modern replacement: any direction, exact match by default, built-in not-found message. | C9: Needs Excel 365/2021+ or Google Sheets.
A10: INDEX/MATCH | B10: Look left, support older Excel, or stay safe when columns change. | C10: Use MATCH(...,0) for exact match.
A11: IF / nested IF | B11: Return different results by condition (profit status, discount band). | C11: Keep nesting shallow; use a lookup table for many tiers.
A12: AND / OR | B12: Combine several conditions inside IF. | C12: Each condition must be a full test.
A13: IFERROR | B13: Show a friendly value instead of an error. | C13: Do not hide real errors – use only where an error is expected.
A14: TRIM / PROPER / UPPER | B14: Clean messy text before lookups and grouping. | C14: TRIM does not remove non-breaking spaces.
... A18: Named ranges | B18: Make formulas readable (SUMIFS(SalesAmt,OrderRegion,...)). | C18: Extend ranges when data grows, or use an Excel Table.
A21: Interview questions
A22: SUMIF vs SUMIFS? | B22: SUMIF handles one condition; SUMIFS handles many. SUMIFS takes sum_range first, SUMIF takes it last.
A23: How does XLOOKUP improve on VLOOKUP? | B23: Looks left or right, exact match by default, no column index number (safe if columns change), has a built-in if_not_found value, and can return multiple columns.
A24: INDEX/MATCH instead of VLOOKUP? | B24: When the return column is to the LEFT of the key, when you need older Excel without XLOOKUP, or when columns may be inserted or deleted.
